<!--
 * @Description: async await
 * @Author: xiao.zhang
 * @Date: 2020-11-23 19:40:16
 * @LastEditors: xiao.zhang
 * @LastEditTime: 2020-12-22 19:52:35
-->
<!DOCTYPE html>
<html lang="en">
  <head>
    <meta charset="UTF-8" />
    <meta name="viewport" content="width=device-width, initial-scale=1.0" />
    <title>Document</title>
  </head>
  <body>
    <script>
      // async返回值是一个Promise实例对象
      // async函数返回的promise的结果由函数执行的结果决定
      async function fn1() {
        // return Promise.resolve(3)
        return new Promise((resolve, reject) => {
          setTimeout(() => {
            resolve(222)
          }, 1000)
        })
      }

      const result = fn1()
      result.then(
        (value) => {
          console.log('onResolved()', value)
        },
        (reason) => {
          console.log('onRejected', reason)
        }
      )
      console.log('result', result)
    </script>

    <script>
      /*
       * 注意：
       * await 必须写在async函数中，但async函数中可以没有await
       * 如果await的promise失败了，就会抛出异常，需要通过try...catch来捕获
       */
      async function fn1() {
        return new Promise((resolve, reject) => {
          setTimeout(() => {
            resolve(222)
          }, 1000)
        })
      }

      function fn2() {
        return Promise.reject(202)
      }

      function fn4() {
        return 6
      }

      async function fn3() {
        // await右侧表达式为promise,得到的结果就是promise返回的value
        // const value = await fn2()
        // await右侧表达不是promise,得到的结果就是表达式的值
        // const value = await fn4()
        // console.log('=====value====', value)

        try {
          const fn1value = await fn1()
          const value2 = await fn2()
          const value4 = await fn4()
        } catch (error) {
          console.log('得到失败的结果', error)
        }
      }
      fn3()
    </script>
  </body>
</html>
